<?xml version="1.0" ?>
<!-- =================================================================================== -->
<!-- |    This document was autogenerated by xacro from welder.xacro                   | -->
<!-- |    EDITING THIS FILE BY HAND IS NOT RECOMMENDED                                 | -->
<!-- =================================================================================== -->
<robot name="welder">
  <ros2_control name="welder" type="system">
    <hardware>
      <plugin>gazebo_ros2_control/GazeboSystem</plugin>
    </hardware>
    <joint name="joint_1">
      <command_interface name="position">
        <param name="min">-3.14</param>
        <param name="max">3.14</param>
      </command_interface>
      <state_interface name="position">
        <param name="initial_value">0.0</param>
      </state_interface>
      <state_interface name="velocity"/>
      <state_interface name="effort"/>
    </joint>
    <joint name="joint_2">
      <command_interface name="position">
        <param name="min">-3.14</param>
        <param name="max">3.14</param>
      </command_interface>
      <state_interface name="position">
        <param name="initial_value">0.0</param>
      </state_interface>
      <state_interface name="velocity"/>
      <state_interface name="effort"/>
    </joint>
    <joint name="joint_3">
      <command_interface name="position">
        <param name="min">-3.14</param>
        <param name="max">3.14</param>
      </command_interface>
      <state_interface name="position">
        <param name="initial_value">0.0</param>
      </state_interface>
      <state_interface name="velocity"/>
      <state_interface name="effort"/>
    </joint>
    <joint name="joint_4">
      <command_interface name="position">
        <param name="min">-3.14</param>
        <param name="max">3.14</param>
      </command_interface>
      <state_interface name="position">
        <param name="initial_value">0.0</param>
      </state_interface>
      <state_interface name="velocity"/>
      <state_interface name="effort"/>
    </joint>
    <joint name="joint_5">
      <command_interface name="position">
        <param name="min">-3.14</param>
        <param name="max">3.14</param>
      </command_interface>
      <state_interface name="position">
        <param name="initial_value">0.0</param>
      </state_interface>
      <state_interface name="velocity"/>
      <state_interface name="effort"/>
    </joint>
    <joint name="joint_6">
      <command_interface name="position">
        <param name="min">-3.14</param>
        <param name="max">3.14</param>
      </command_interface>
      <state_interface name="position">
        <param name="initial_value">0.0</param>
      </state_interface>
      <state_interface name="velocity"/>
      <state_interface name="effort"/>
    </joint>
  </ros2_control>
  <transmission name="joint_1_tran">
    <type>transmission_interface/SimpleTransmission</type>
    <joint name="joint_1">
      <hardwareInterface>hardware_interface/EffortJointInterface</hardwareInterface>
    </joint>
    <actuator name="joint_1_actr">
      <hardwareInterface>hardware_interface/EffortJointInterface</hardwareInterface>
      <mechanicalReduction>1</mechanicalReduction>
    </actuator>
  </transmission>
  <transmission name="joint_2_tran">
    <type>transmission_interface/SimpleTransmission</type>
    <joint name="joint_2">
      <hardwareInterface>hardware_interface/EffortJointInterface</hardwareInterface>
    </joint>
    <actuator name="joint_2_actr">
      <hardwareInterface>hardware_interface/EffortJointInterface</hardwareInterface>
      <mechanicalReduction>1</mechanicalReduction>
    </actuator>
  </transmission>
  <transmission name="joint_3_tran">
    <type>transmission_interface/SimpleTransmission</type>
    <joint name="joint_3">
      <hardwareInterface>hardware_interface/EffortJointInterface</hardwareInterface>
    </joint>
    <actuator name="joint_3_actr">
      <hardwareInterface>hardware_interface/EffortJointInterface</hardwareInterface>
      <mechanicalReduction>1</mechanicalReduction>
    </actuator>
  </transmission>
  <transmission name="joint_4_tran">
    <type>transmission_interface/SimpleTransmission</type>
    <joint name="joint_4">
      <hardwareInterface>hardware_interface/EffortJointInterface</hardwareInterface>
    </joint>
    <actuator name="joint_4_actr">
      <hardwareInterface>hardware_interface/EffortJointInterface</hardwareInterface>
      <mechanicalReduction>1</mechanicalReduction>
    </actuator>
  </transmission>
  <transmission name="joint_5_tran">
    <type>transmission_interface/SimpleTransmission</type>
    <joint name="joint_5">
      <hardwareInterface>hardware_interface/EffortJointInterface</hardwareInterface>
    </joint>
    <actuator name="joint_5_actr">
      <hardwareInterface>hardware_interface/EffortJointInterface</hardwareInterface>
      <mechanicalReduction>1</mechanicalReduction>
    </actuator>
  </transmission>
  <transmission name="joint_6_tran">
    <type>transmission_interface/SimpleTransmission</type>
    <joint name="joint_6">
      <hardwareInterface>hardware_interface/EffortJointInterface</hardwareInterface>
    </joint>
    <actuator name="joint_6_actr">
      <hardwareInterface>hardware_interface/EffortJointInterface</hardwareInterface>
      <mechanicalReduction>1</mechanicalReduction>
    </actuator>
  </transmission>
  <gazebo>
    <plugin filename="libgazebo_ros2_control.so" name="gazebo_ros2_control">
      <robot_sim_type>gazebo_ros2_control/GazeboSystem</robot_sim_type>
      <parameters>/home/kriso/arm_tuto_WS/install/welder_description/share/welder_description/config/my_controllers.yaml</parameters>
    </plugin>
  </gazebo>
  <gazebo reference="base_link">
    <material>Gazebo/White</material>
    <mu1>0.2</mu1>
    <mu2>0.2</mu2>
    <self_collide>true</self_collide>
    <gravity>true</gravity>
  </gazebo>
  <gazebo reference="link_1_1">
    <material>Gazebo/Red</material>
    <mu1>0.2</mu1>
    <mu2>0.2</mu2>
    <self_collide>true</self_collide>
  </gazebo>
  <gazebo reference="link_2_1">
    <material>Gazebo/Green</material>
    <mu1>0.2</mu1>
    <mu2>0.2</mu2>
    <self_collide>true</self_collide>
  </gazebo>
  <gazebo reference="link_3_1">
    <material>Gazebo/Blue</material>
    <mu1>0.2</mu1>
    <mu2>0.2</mu2>
    <self_collide>true</self_collide>
  </gazebo>
  <gazebo reference="link_4_1">
    <material>Gazebo/Yellow</material>
    <mu1>0.2</mu1>
    <mu2>0.2</mu2>
    <self_collide>true</self_collide>
  </gazebo>
  <gazebo reference="link_5_1">
    <material>Gazebo/Orange</material>
    <mu1>0.2</mu1>
    <mu2>0.2</mu2>
    <self_collide>true</self_collide>
  </gazebo>
  <gazebo reference="link_6_1">
    <material>Gazebo/Silver</material>
    <mu1>0.2</mu1>
    <mu2>0.2</mu2>
    <self_collide>true</self_collide>
  </gazebo>
  <link name="world">
  
</link>
  <link name="base_link">
    <inertial>
      <origin rpy="0 0 0" xyz="-7.16285389829585e-11 -1.5064593165281103e-11 0.019107627086653742"/>
      <mass value="2.955437891841375"/>
      <inertia ixx="0.002819" ixy="-0.0" ixz="-0.0" iyy="0.002819" iyz="-0.0" izz="0.004764"/>
    </inertial>
    <visual>
      <origin rpy="0 0 0" xyz="0 0 0"/>
      <geometry>
        <mesh filename="package://welder_description/meshes/base_link.stl" scale="0.001 0.001 0.001"/>
      </geometry>
    </visual>
    <collision>
      <origin rpy="0 0 0" xyz="0 0 0"/>
      <geometry>
        <mesh filename="package://welder_description/meshes/base_link.stl" scale="0.001 0.001 0.001"/>
      </geometry>
    </collision>
  </link>
  <link name="link_1_1">
    <inertial>
      <origin rpy="0 0 0" xyz="0.0 0.0009431909165482249 0.11440920058437602"/>
      <mass value="2.2877730999420254"/>
      <inertia ixx="0.009859" ixy="0.0" ixz="0.0" iyy="0.009807" iyz="-0.000185" izz="0.000515"/>
    </inertial>
    <visual>
      <origin rpy="0 0 0" xyz="-0.0 -0.0 -0.05"/>
      <geometry>
        <mesh filename="package://welder_description/meshes/link_1_1.stl" scale="0.001 0.001 0.001"/>
      </geometry>
    </visual>
    <collision>
      <origin rpy="0 0 0" xyz="-0.0 -0.0 -0.05"/>
      <geometry>
        <mesh filename="package://welder_description/meshes/link_1_1.stl" scale="0.001 0.001 0.001"/>
      </geometry>
    </collision>
  </link>
  <link name="link_2_1">
    <inertial>
      <origin rpy="0 0 0" xyz="0.0 -0.02834196834303381 -0.012543410312423592"/>
      <mass value="0.8650806084810733"/>
      <inertia ixx="0.000478" ixy="0.0" ixz="0.0" iyy="0.0004" iyz="-1.8e-05" izz="0.000257"/>
    </inertial>
    <visual>
      <origin rpy="0 0 0" xyz="-0.0 0.02 -0.25"/>
      <geometry>
        <mesh filename="package://welder_description/meshes/link_2_1.stl" scale="0.001 0.001 0.001"/>
      </geometry>
    </visual>
    <collision>
      <origin rpy="0 0 0" xyz="-0.0 0.02 -0.25"/>
      <geometry>
        <mesh filename="package://welder_description/meshes/link_2_1.stl" scale="0.001 0.001 0.001"/>
      </geometry>
    </collision>
  </link>
  <link name="link_3_1">
    <inertial>
      <origin rpy="0 0 0" xyz="0.0 -0.0009734727614764405 -0.056920756556270824"/>
      <mass value="1.1630985552142648"/>
      <inertia ixx="0.001298" ixy="0.0" ixz="0.0" iyy="0.00127" iyz="-3.8e-05" izz="0.000267"/>
    </inertial>
    <visual>
      <origin rpy="0 0 0" xyz="-0.0 0.05 -0.2"/>
      <geometry>
        <mesh filename="package://welder_description/meshes/link_3_1.stl" scale="0.001 0.001 0.001"/>
      </geometry>
    </visual>
    <collision>
      <origin rpy="0 0 0" xyz="-0.0 0.05 -0.2"/>
      <geometry>
        <mesh filename="package://welder_description/meshes/link_3_1.stl" scale="0.001 0.001 0.001"/>
      </geometry>
    </collision>
  </link>
  <link name="link_4_1">
    <inertial>
      <origin rpy="0 0 0" xyz="0.0 -0.024901368509315194 0.031832335951871196"/>
      <mass value="1.2085805984841382"/>
      <inertia ixx="0.001374" ixy="0.0" ixz="0.0" iyy="0.001327" iyz="4e-06" izz="0.000295"/>
    </inertial>
    <visual>
      <origin rpy="0 0 0" xyz="-0.0 0.075 -0.11"/>
      <geometry>
        <mesh filename="package://welder_description/meshes/link_4_1.stl" scale="0.001 0.001 0.001"/>
      </geometry>
    </visual>
    <collision>
      <origin rpy="0 0 0" xyz="-0.0 0.075 -0.11"/>
      <geometry>
        <mesh filename="package://welder_description/meshes/link_4_1.stl" scale="0.001 0.001 0.001"/>
      </geometry>
    </collision>
  </link>
  <link name="link_5_1">
    <inertial>
      <origin rpy="0 0 0" xyz="0.0 -4.404769588479962e-05 0.03489668781804081"/>
      <mass value="0.7187100595069817"/>
      <inertia ixx="0.000352" ixy="-0.0" ixz="0.0" iyy="0.000343" iyz="1e-06" izz="0.000159"/>
    </inertial>
    <visual>
      <origin rpy="0 0 0" xyz="-0.0 0.1 -0.2"/>
      <geometry>
        <mesh filename="package://welder_description/meshes/link_5_1.stl" scale="0.001 0.001 0.001"/>
      </geometry>
    </visual>
    <collision>
      <origin rpy="0 0 0" xyz="-0.0 0.1 -0.2"/>
      <geometry>
        <mesh filename="package://welder_description/meshes/link_5_1.stl" scale="0.001 0.001 0.001"/>
      </geometry>
    </collision>
  </link>
  <link name="link_6_1">
    <inertial>
      <origin rpy="0 0 0" xyz="0.0 -0.01680268432280871 1.6653345369377348e-16"/>
      <mass value="0.26501912859947435"/>
      <inertia ixx="5.2e-05" ixy="0.0" ixz="-0.0" iyy="3.9e-05" iyz="-0.0" izz="5.2e-05"/>
    </inertial>
    <visual>
      <origin rpy="0 0 0" xyz="-0.0 0.12 -0.25"/>
      <geometry>
        <mesh filename="package://welder_description/meshes/link_6_1.stl" scale="0.001 0.001 0.001"/>
      </geometry>
    </visual>
    <collision>
      <origin rpy="0 0 0" xyz="-0.0 0.12 -0.25"/>
      <geometry>
        <mesh filename="package://welder_description/meshes/link_6_1.stl" scale="0.001 0.001 0.001"/>
      </geometry>
    </collision>
  </link>
  <joint name="world_joint" type="fixed">
    <parent link="world"/>
    <child link="base_link"/>
  </joint>
  <joint name="joint_1" type="continuous">
    <origin rpy="0 0 0" xyz="0.0 0.0 0.05"/>
    <parent link="base_link"/>
    <child link="link_1_1"/>
    <axis xyz="0.0 0.0 1.0"/>
  </joint>
  <joint name="joint_2" type="continuous">
    <origin rpy="0 0 0" xyz="0.0 -0.02 0.2"/>
    <parent link="link_1_1"/>
    <child link="link_2_1"/>
    <axis xyz="0.0 -1.0 0.0"/>
  </joint>
  <joint name="joint_3" type="continuous">
    <origin rpy="0 0 0" xyz="0.0 -0.03 -0.05"/>
    <parent link="link_2_1"/>
    <child link="link_3_1"/>
    <axis xyz="0.0 0.0 -1.0"/>
  </joint>
  <joint name="joint_4" type="continuous">
    <origin rpy="0 0 0" xyz="0.0 -0.025 -0.09"/>
    <parent link="link_3_1"/>
    <child link="link_4_1"/>
    <axis xyz="0.0 1.0 0.0"/>
  </joint>
  <joint name="joint_5" type="continuous">
    <origin rpy="0 0 0" xyz="0.0 -0.025 0.09"/>
    <parent link="link_4_1"/>
    <child link="link_5_1"/>
    <axis xyz="0.0 0.0 1.0"/>
  </joint>
  <joint name="joint_6" type="continuous">
    <origin rpy="0 0 0" xyz="0.0 -0.02 0.05"/>
    <parent link="link_5_1"/>
    <child link="link_6_1"/>
    <axis xyz="0.0 -1.0 0.0"/>
  </joint>
</robot>
